Workbook

Sheet 核心数据
A1: S4 回测核心数据（50 万本金，半仓，保证金 12%，手续费交易所加一分钱，复利）
A3: 指标 | B3: 数值 | C3: 说明
A4: 初始资金（元） | B4: =参数说明!B4 -> 500000
A5: 期末权益（元） | B5: =资金曲线!C3305 -> 2.7492538e+08 | C5: 2026-10-29 收盘，含当时持仓的浮动盈亏
A6: 总收益率 | B6: =B5/B4-1 -> 548.85076
A7: 回测年数 | B7: =(资金曲线!A3305-资金曲线!A2)/365.25 -> 13.604381 | C7: 2013-03-22 至 2026-10-29
A8: 年化收益率 | B8: =(B5/B4)^(1/B7)-1 -> 0.59009734
A9: 最大回撤 | B9: =MIN(资金曲线!E2:E3305) -> -0.81212991 | C9: 按每日收盘权益计算
A10: 最大回撤谷底日期 | B10: =INDEX(资金曲线!A2:A3305,MATCH(B9,资金曲线!E2:E3305,0)) -> 44585
A11: 卡玛比率（年化 ÷ 最大回撤） | B11: =B8/ABS(B9) -> 0.72660461
A12: 交易次数 | B12: =COUNT(逐笔交易!$I$2:$I$65) -> 64
A13: 年均交易次数 | B13: =B12/B7 -> 4.7043671
A14: 盈利笔数 | B14: =COUNTIF(逐笔交易!$I$2:$I$65,">0") -> 35
A15: 亏损笔数 | B15: =COUNTIF(逐笔交易!$I$2:$I$65,"<=0") -> 29
A16: 胜率 | B16: =B14/B12 -> 0.546875
A17: 平均盈利（元） | B17: =AVERAGEIF(逐笔交易!$I$2:$I$65,">0") -> 26375118
A18: 平均亏损（元） | B18: =AVERAGEIF(逐笔交易!$I$2:$I$65,"<=0") -> -22369095
A19: 盈亏比（按金额） | B19: =B17/ABS(B18) -> 1.1790874 | C19: 复利时后期仓位巨大，金额口径被最后几年主导，参考价值有限
A20: 平均盈利占当时权益 | B20: =AVERAGEIF(逐笔交易!$I$2:$I$65,">0",逐笔交易!$K$2:$K$65) -> 0.58737249
A21: 平均亏损占当时权益 | B21: =AVERAGEIF(逐笔交易!$I$2:$I$65,"<=0",逐笔交易!$K$2:$K$65) -> -0.2226485
A22: 盈亏比（按占权益比例） | B22: =B20/ABS(B21) -> 2.6381156 | C22: 更能反映策略本身
A23: 利润因子（总盈利 ÷ 总亏损） | B23: =SUMIF(逐笔交易!$I$2:$I$65,">0")/ABS(SUMIF(逐笔交易!$I$2:$I$65,"<=0")) -> 1.4230365
A24: 每笔平均盈亏（元） | B24: =AVERAGE(逐笔交易!$I$2:$I$65) -> 4287896.5
A25: 单笔最大盈利（元） | B25: =MAX(逐笔交易!$I$2:$I$65) -> 4.5930391e+08
A26: 单笔最大盈利占权益 | B26: =MAX(逐笔交易!$K$2:$K$65) -> 3.4903135
A27: 单笔最大亏损（元） | B27: =MIN(逐笔交易!$I$2:$I$65) -> -2.4839759e+08
A28: 单笔最大亏损占权益 | B28: =MIN(逐笔交易!$K$2:$K$65) -> -0.59511002
A29: 最大连续亏损（笔） | B29: =MAX(逐笔交易!$O$2:$O$65) -> 4
A30: 最大连续盈利（笔） | B30: =MAX(逐笔交易!$P$2:$P$65) -> 4
A31: 平均持仓天数（交易日） | B31: =AVERAGE(逐笔交易!$H$2:$H$65) -> 33.703125
A32: 盈利单平均持仓天数 | B32: =AVERAGEIF(逐笔交易!$I$2:$I$65,">0",逐笔交易!$H$2:$H$65) -> 46.342857
A33: 亏损单平均持仓天数 | B33: =AVERAGEIF(逐笔交易!$I$2:$I$65,"<=0",逐笔交易!$H$2:$H$65) -> 18.448276
A34: 慢SAR翻转离场笔数 | B34: =COUNTIF(逐笔交易!$M$2:$M$65,"慢SAR翻转离场") -> 51
A35: 止损离场笔数 | B35: =COUNTIF(逐笔交易!$M$2:$M$65,"止损") -> 12
A36: 多单笔数 | B36: =COUNTIF(逐笔交易!$B$2:$B$65,"多") -> 32
A37: 多单胜率 | B37: =COUNTIFS(逐笔交易!$B$2:$B$65,"多",逐笔交易!$I$2:$I$65,">0")/B36 -> 0.53125
A38: 多单盈亏合计（元） | B38: =SUMIF(逐笔交易!$B$2:$B$65,"多",逐笔交易!$I$2:$I$65) -> 3.2780409e+08
A39: 空单笔数 | B39: =COUNTIF(逐笔交易!$B$2:$B$65,"空") -> 32
A40: 空单胜率 | B40: =COUNTIFS(逐笔交易!$B$2:$B$65,"空",逐笔交易!$I$2:$I$65,">0")/B39 -> 0.5625
A41: 空单盈亏合计（元） | B41: =SUMIF(逐笔交易!$B$2:$B$65,"空",逐笔交易!$I$2:$I$65) -> -53378707
...

Sheet 年度收益
A1: 年份 | B1: 年末日期 | C1: 年初权益（元） | D1: 年末权益（元） | E1: 年收益率 | F1: 开仓笔数 | G1: 当年平仓盈亏（元）
A2: 2013 | B2: =_xlfn.MAXIFS(资金曲线!$A$2:$A$3305,资金曲线!$F$2:$F$3305,A2) -> 41639 | C2: =参数说明!$B$4 -> 500000 | D2: =INDEX(资金曲线!$C$2:$C$3305,MATCH(B2,资金曲线!$A$2:$A$3305,0)) -> 657516.91 | E2: =D2/C2-1 -> 0.31503382 | F2: =COUNTIFS(逐笔交易!$C$2:$C$65,">="&DATE(A2,1,1),逐笔交易!$C$2:$C$65,"<="&DATE(A2,12,31)) -> 3 | G2: =SUMIFS(逐笔交易!$I$2:$I$65,逐笔交易!$E$2:$E$65,">="&DATE(A2,1,1),逐笔交易!$E$2:$E$65,"<="&DATE(A2,12,31)) -> 157516.91
A3: 2014 | B3: =_xlfn.MAXIFS(资金曲线!$A$2:$A$3305,资金曲线!$F$2:$F$3305,A3) -> 42004 | C3: =D2 -> 657516.91 | D3: =INDEX(资金曲线!$C$2:$C$3305,MATCH(B3,资金曲线!$A$2:$A$3305,0)) -> 545567.65 | E3: =D3/C3-1 -> -0.17026066 | F3: =COUNTIFS(逐笔交易!$C$2:$C$65,">="&DATE(A3,1,1),逐笔交易!$C$2:$C$65,"<="&DATE(A3,12,31)) -> 6 | G3: =SUMIFS(逐笔交易!$I$2:$I$65,逐笔交易!$E$2:$E$65,">="&DATE(A3,1,1),逐笔交易!$E$2:$E$65,"<="&DATE(A3,12,31)) -> -111949.26
A4: 2015 | B4: =_xlfn.MAXIFS(资金曲线!$A$2:$A$3305,资金曲线!$F$2:$F$3305,A4) -> 42369 | C4: =D3 -> 545567.65 | D4: =INDEX(资金曲线!$C$2:$C$3305,MATCH(B4,资金曲线!$A$2:$A$3305,0)) -> 912617.38 | E4: =D4/C4-1 -> 0.672785 | F4: =COUNTIFS(逐笔交易!$C$2:$C$65,">="&DATE(A4,1,1),逐笔交易!$C$2:$C$65,"<="&DATE(A4,12,31)) -> 5 | G4: =SUMIFS(逐笔交易!$I$2:$I$65,逐笔交易!$E$2:$E$65,">="&DATE(A4,1,1),逐笔交易!$E$2:$E$65,"<="&DATE(A4,12,31)) -> 244378.03
A5: 2016 | B5: =_xlfn.MAXIFS(资金曲线!$A$2:$A$3305,资金曲线!$F$2:$F$3305,A5) -> 42734 | C5: =D4 -> 912617.38 | D5: =INDEX(资金曲线!$C$2:$C$3305,MATCH(B5,资金曲线!$A$2:$A$3305,0)) -> 6170306.3 | E5: =D5/C5-1 -> 5.7611098 | F5: =COUNTIFS(逐笔交易!$C$2:$C$65,">="&DATE(A5,1,1),逐笔交易!$C$2:$C$65,"<="&DATE(A5,12,31)) -> 4 | G5: =SUMIFS(逐笔交易!$I$2:$I$65,逐笔交易!$E$2:$E$65,">="&DATE(A5,1,1),逐笔交易!$E$2:$E$65,"<="&DATE(A5,12,31)) -> 2881684.6
A6: 2017 | B6: =_xlfn.MAXIFS(资金曲线!$A$2:$A$3305,资金曲线!$F$2:$F$3305,A6) -> 43098 | C6: =D5 -> 6170306.3 | D6: =INDEX(资金曲线!$C$2:$C$3305,MATCH(B6,资金曲线!$A$2:$A$3305,0)) -> 19561833 | E6: =D6/C6-1 -> 2.170318 | F6: =COUNTIFS(逐笔交易!$C$2:$C$65,">="&DATE(A6,1,1),逐笔交易!$C$2:$C$65,"<="&DATE(A6,12,31)) -> 6 | G6: =SUMIFS(逐笔交易!$I$2:$I$65,逐笔交易!$E$2:$E$65,">="&DATE(A6,1,1),逐笔交易!$E$2:$E$65,"<="&DATE(A6,12,31)) -> 17506431
A7: 2018 | B7: =_xlfn.MAXIFS(资金曲线!$A$2:$A$3305,资金曲线!$F$2:$F$3305,A7) -> 43462 | C7: =D6 -> 19561833 | D7: =INDEX(资金曲线!$C$2:$C$3305,MATCH(B7,资金曲线!$A$2:$A$3305,0)) -> 18694689 | E7: =D7/C7-1 -> -0.044328348 | F7: =COUNTIFS(逐笔交易!$C$2:$C$65,">="&DATE(A7,1,1),逐笔交易!$C$2:$C$65,"<="&DATE(A7,12,31)) -> 5 | G7: =SUMIFS(逐笔交易!$I$2:$I$65,逐笔交易!$E$2:$E$65,">="&DATE(A7,1,1),逐笔交易!$E$2:$E$65,"<="&DATE(A7,12,31)) -> -8292176.6
A8: 2019 | B8: =_xlfn.MAXIFS(资金曲线!$A$2:$A$3305,资金曲线!$F$2:$F$3305,A8) -> 43830 | C8: =D7 -> 18694689 | D8: =INDEX(资金曲线!$C$2:$C$3305,MATCH(B8,资金曲线!$A$2:$A$3305,0)) -> 17241341 | E8: =D8/C8-1 -> -0.077741215 | F8: =COUNTIFS(逐笔交易!$C$2:$C$65,">="&DATE(A8,1,1),逐笔交易!$C$2:$C$65,"<="&DATE(A8,12,31)) -> 5 | G8: =SUMIFS(逐笔交易!$I$2:$I$65,逐笔交易!$E$2:$E$65,">="&DATE(A8,1,1),逐笔交易!$E$2:$E$65,"<="&DATE(A8,12,31)) -> 3550868.7
A9: 2020 | B9: =_xlfn.MAXIFS(资金曲线!$A$2:$A$3305,资金曲线!$F$2:$F$3305,A9) -> 44196 | C9: =D8 -> 17241341 | D9: =INDEX(资金曲线!$C$2:$C$3305,MATCH(B9,资金曲线!$A$2:$A$3305,0)) -> 24738409 | E9: =D9/C9-1 -> 0.43483086 | F9: =COUNTIFS(逐笔交易!$C$2:$C$65,">="&DATE(A9,1,1),逐笔交易!$C$2:$C$65,"<="&DATE(A9,12,31)) -> 6 | G9: =SUMIFS(逐笔交易!$I$2:$I$65,逐笔交易!$E$2:$E$65,">="&DATE(A9,1,1),逐笔交易!$E$2:$E$65,"<="&DATE(A9,12,31)) -> -1224982.8
A10: 2021 | B10: =_xlfn.MAXIFS(资金曲线!$A$2:$A$3305,资金曲线!$F$2:$F$3305,A10) -> 44561 | C10: =D9 -> 24738409 | D10: =INDEX(资金曲线!$C$2:$C$3305,MATCH(B10,资金曲线!$A$2:$A$3305,0)) -> 14538744 | E10: =D10/C10-1 -> -0.41230075 | F10: =COUNTIFS(逐笔交易!$C$2:$C$65,">="&DATE(A10,1,1),逐笔交易!$C$2:$C$65,"<="&DATE(A10,12,31)) -> 5 | G10: =SUMIFS(逐笔交易!$I$2:$I$65,逐笔交易!$E$2:$E$65,">="&DATE(A10,1,1),逐笔交易!$E$2:$E$65,"<="&DATE(A10,12,31)) -> -673026.12
A11: 2022 | B11: =_xlfn.MAXIFS(资金曲线!$A$2:$A$3305,资金曲线!$F$2:$F$3305,A11) -> 44925 | C11: =D10 -> 14538744 | D11: =INDEX(资金曲线!$C$2:$C$3305,MATCH(B11,资金曲线!$A$2:$A$3305,0)) -> 29961823 | E11: =D11/C11-1 -> 1.0608261 | F11: =COUNTIFS(逐笔交易!$C$2:$C$65,">="&DATE(A11,1,1),逐笔交易!$C$2:$C$65,"<="&DATE(A11,12,31)) -> 5 | G11: =SUMIFS(逐笔交易!$I$2:$I$65,逐笔交易!$E$2:$E$65,">="&DATE(A11,1,1),逐笔交易!$E$2:$E$65,"<="&DATE(A11,12,31)) -> 27851575
A12: 2023 | B12: =_xlfn.MAXIFS(资金曲线!$A$2:$A$3305,资金曲线!$F$2:$F$3305,A12) -> 45289 | C12: =D11 -> 29961823 | D12: =INDEX(资金曲线!$C$2:$C$3305,MATCH(B12,资金曲线!$A$2:$A$3305,0)) -> 59749116 | E12: =D12/C12-1 -> 0.9941749 | F12: =COUNTIFS(逐笔交易!$C$2:$C$65,">="&DATE(A12,1,1),逐笔交易!$C$2:$C$65,"<="&DATE(A12,12,31)) -> 4 | G12: =SUMIFS(逐笔交易!$I$2:$I$65,逐笔交易!$E$2:$E$65,">="&DATE(A12,1,1),逐笔交易!$E$2:$E$65,"<="&DATE(A12,12,31)) -> 17358797
A13: 2024 | B13: =_xlfn.MAXIFS(资金曲线!$A$2:$A$3305,资金曲线!$F$2:$F$3305,A13) -> 45657 | C13: =D12 -> 59749116 | D13: =INDEX(资金曲线!$C$2:$C$3305,MATCH(B13,资金曲线!$A$2:$A$3305,0)) -> 1.2811979e+08 | E13: =D13/C13-1 -> 1.144296 | F13: =COUNTIFS(逐笔交易!$C$2:$C$65,">="&DATE(A13,1,1),逐笔交易!$C$2:$C$65,"<="&DATE(A13,12,31)) -> 4 | G13: =SUMIFS(逐笔交易!$I$2:$I$65,逐笔交易!$E$2:$E$65,">="&DATE(A13,1,1),逐笔交易!$E$2:$E$65,"<="&DATE(A13,12,31)) -> 34311827
A14: 2025 | B14: =_xlfn.MAXIFS(资金曲线!$A$2:$A$3305,资金曲线!$F$2:$F$3305,A14) -> 46022 | C14: =D13 -> 1.2811979e+08 | D14: =INDEX(资金曲线!$C$2:$C$3305,MATCH(B14,资金曲线!$A$2:$A$3305,0)) -> 6.0129295e+08 | E14: =D14/C14-1 -> 3.6932089 | F14: =COUNTIFS(逐笔交易!$C$2:$C$65,">="&DATE(A14,1,1),逐笔交易!$C$2:$C$65,"<="&DATE(A14,12,31)) -> 3 | G14: =SUMIFS(逐笔交易!$I$2:$I$65,逐笔交易!$E$2:$E$65,">="&DATE(A14,1,1),逐笔交易!$E$2:$E$65,"<="&DATE(A14,12,31)) -> 6.4116867e+08
A15: 2026 | B15: =_xlfn.MAXIFS(资金曲线!$A$2:$A$3305,资金曲线!$F$2:$F$3305,A15) -> 46324 | C15: =D14 -> 6.0129295e+08 | D15: =INDEX(资金曲线!$C$2:$C$3305,MATCH(B15,资金曲线!$A$2:$A$3305,0)) -> 2.7492538e+08 | E15: =D15/C15-1 -> -0.54277632 | F15: =COUNTIFS(逐笔交易!$C$2:$C$65,">="&DATE(A15,1,1),逐笔交易!$C$2:$C$65,"<="&DATE(A15,12,31)) -> 3 | G15: =SUMIFS(逐笔交易!$I$2:$I$65,逐笔交易!$E$2:$E$65,">="&DATE(A15,1,1),逐笔交易!$E$2:$E$65,"<="&DATE(A15,12,31)) -> -4.6030424e+08

Sheet 图表

Sheet 参数说明
A1: S4 焦煤加权回测：参数与交易规则
A3: 参数 | B3: 数值 | C3: 说明 / 来源
A4: 初始资金（元） | B4: 500000 | C4: 用户设定
A5: 每次开仓保证金占权益比例 | B5: 0.5 | C5: 用户设定（半仓），每次按开仓时的账户权益计算手数（复利）
A6: 保证金比例 | B6: 0.12 | C6: 交易所标准，期货公司不上浮；12% 来自网络搜索结果，未能在大商所官网核实
A7: 合约乘数（吨/手） | B7: 60 | C7: 大商所焦煤合约
A8: 手续费率（每边，按成交额） | B8: 0.0001 | C8: 交易所标准万分之一（网络资料，未核实）
A9: 平今平仓手续费率 | B9: 0.0002 | C9: 当天开当天平；2025-08 起可能为万分之二（网络资料，未核实）
A10: 每边每手另加手续费（元） | B10: 0.01 | C10: 用户设定：交易所加一分钱
A11: 滑点（每边，元/吨） | B11: 0.5 | C11: 按 1 个最小变动价位假设
A12: 回测数据 | B12: 焦煤加权日线 | C12: 用户提供，2013-03-22（上市首日）至 2026-10-29，共 3304 根 K 线
A14: 注意 | C14: “逐笔交易”“资金曲线”两张表是 Python 回测程序（run_s4.py）的输出数值；修改上面的参数不会重新回测，需要重跑程序。“核心数据”“年度收益”由公式从这两张表计算。
A16: 交易规则（多空对称，以做多为例）
A17: 用到的指标 | B17: 灵敏 SAR(5, 3%, 30%) 抓转折；指标“1”（简化 STM = (MA5−MA20) + (DIF−DEA)×5 + (RSI14−50)/2）确认方向；慢 SAR(10, 0.5%, 5%) 跟踪止盈；ATR(14) 定止损
A18: 准备 | B18: 灵敏 SAR 还在 K 线上方，指标“1”已在零轴上方或绿柱快速缩短，价格逼近 SAR 点
A19: 进场 | B19: 同一根日 K 线收盘时：灵敏 SAR 由空翻多，且指标“1” > 0 → 次日开盘买入。翻转当天指标“1”仍 < 0 则放弃这次信号
A20: 做空 | B20: 灵敏 SAR 由多翻空，且指标“1” < 0 → 次日开盘卖出
A21: 止损 | B21: 入场价 − 2.5 × ATR(14)（取信号当天 ATR），固定不动；盘中触及即平，跳空越过按开盘价成交
A22: 止盈/离场 | B22: 持仓期间慢 SAR 由多翻空（入场后发生的翻转）→ 次日开盘平仓；没有固定目标价
A23: 持仓期间 | B23: 不加仓、不反手，只看慢 SAR 与止损；平仓后空仓等待下一个信号
A24: 仓位 | B24: 手数 = 开仓时权益 × 50% ÷（开仓价 × 60 × 保证金比例），向下取整

Sheet 逐笔交易
A1: 序号 | B1: 方向 | C1: 开仓日期 | D1: 开仓价 | E1: 平仓日期 | F1: 平仓价 | G1: 手数 | H1: 持仓天数 | I1: 净盈亏（元） | J1: 开仓前权益（元） | K1: 盈亏占权益 | L1: R 倍数 | M1: 离场原因 | N1: 名义杠杆 | O1: 连亏计数 | P1: 连赢计数
A2: 1 | B2: 多 | C2: 41467 | D2: 1062.5 | E2: 41533 | F2: 1143.5 | G2: 32 | H2: 46 | I2: 155095.81 | J2: =参数说明!$B$4 -> 500000 | K2: =I2/J2 -> 0.31019162 | L2: 1.564 | M2: 慢SAR翻转离场 | N2: =G2*D2*参数说明!$B$7/J2 -> 4.08 | O2: =IF(I2<=0,1,0) -> 0 | P2: =IF(I2>0,1,0) -> 1
A3: 2 | B3: 空 | C3: 41555 | D3: 1149.5 | E3: 41613 | F3: 1116.5 | G3: 39 | H3: 42 | I3: 76688.976 | J3: =J2+I2 -> 655095.81 | K3: =I3/J3 -> 0.11706528 | L3: 0.786 | M3: 慢SAR翻转离场 | N3: =G3*D3*参数说明!$B$7/J3 -> 4.1060101 | O3: =IF(I3<=0,O2+1,0) -> 0 | P3: =IF(I3>0,P2+1,0) -> 2
A4: 3 | B4: 多 | C4: 41613 | D4: 1116.5 | E4: 41621 | F4: 1089.2143 | G4: 45 | H4: 6 | I4: -74267.871 | J4: =J3+I3 -> 731784.78 | K4: =I4/J4 -> -0.10148868 | L4: -1.019 | M4: 止损 | N4: =G4*D4*参数说明!$B$7/J4 -> 4.1194489 | O4: =IF(I4<=0,O3+1,0) -> 1 | P4: =IF(I4>0,P3+1,0) -> 0
A5: 4 | B5: 空 | C5: 41652 | D5: 991.5 | E5: 41733 | F5: 845.5 | G5: 46 | H5: 54 | I5: 402452.07 | J5: =J4+I4 -> 657516.91 | K5: =I5/J5 -> 0.61207866 | L5: 3.539 | M5: 慢SAR翻转离场 | N5: =G5*D5*参数说明!$B$7/J5 -> 4.161931 | O5: =IF(I5<=0,O4+1,0) -> 0 | P5: =IF(I5>0,P4+1,0) -> 1
A6: 5 | B6: 空 | C6: 41778 | D6: 819.5 | E6: 41857 | F6: 794.5 | G6: 89 | H6: 56 | I6: 132636.34 | J6: =J5+I5 -> 1059969 | K6: =I6/J6 -> 0.12513229 | L6: 0.511 | M6: 慢SAR翻转离场 | N6: =G6*D6*参数说明!$B$7/J6 -> 4.1285453 | O6: =IF(I6<=0,O5+1,0) -> 0 | P6: =IF(I6>0,P5+1,0) -> 2
A7: 6 | B7: 多 | C7: 41876 | D7: 794.5 | E7: 41892 | F7: 769.5 | G7: 104 | H7: 11 | I7: -156978.02 | J7: =J6+I6 -> 1192605.3 | K7: =I7/J7 -> -0.13162612 | L7: -0.642 | M7: 慢SAR翻转离场 | N7: =G7*D7*参数说明!$B$7/J7 -> 4.1570165 | O7: =IF(I7<=0,O6+1,0) -> 1 | P7: =IF(I7>0,P6+1,0) -> 0
A8: 7 | B8: 空 | C8: 41905 | D8: 777.5 | E8: 41921 | F8: 816.92857 | G8: 92 | H8: 7 | I8: -218527.68 | J8: =J7+I7 -> 1035627.3 | K8: =I8/J8 -> -0.21100996 | L8: -1.013 | M8: 止损 | N8: =G8*D8*参数说明!$B$7/J8 -> 4.1441549 | O8: =IF(I8<=0,O7+1,0) -> 2 | P8: =IF(I8>0,P7+1,0) -> 0
A9: 8 | B9: 多 | C9: 41922 | D9: 813.5 | E9: 41934 | F9: 770.5 | G9: 69 | H9: 8 | I9: -178677.16 | J9: =J8+I8 -> 817099.63 | K9: =I9/J9 -> -0.21867242 | L9: -1.012 | M9: 止损 | N9: =G9*D9*参数说明!$B$7/J9 -> 4.1217618 | O9: =IF(I9<=0,O8+1,0) -> 3 | P9: =IF(I9>0,P8+1,0) -> 0
A10: 9 | B10: 多 | C10: 41976 | D10: 764.5 | E10: 41996 | F10: 737.5 | G10: 57 | H10: 14 | I10: -92854.824 | J10: =J9+I9 -> 638422.47 | K10: =I10/J10 -> -0.14544417 | L10: -0.975 | M10: 慢SAR翻转离场 | N10: =G10*D10*参数说明!$B$7/J10 -> 4.0953915 | O10: =IF(I10<=0,O9+1,0) -> 4 | P10: =IF(I10>0,P9+1,0) -> 0
A11: 10 | B11: 空 | C11: 42017 | D11: 727.5 | E11: 42122 | F11: 684 | G11: 52 | H11: 69 | I11: 135278.57 | J11: =J10+I10 -> 545567.65 | K11: =I11/J11 -> 0.2479593 | L11: 1.083 | M11: 慢SAR翻转离场 | N11: =G11*D11*参数说明!$B$7/J11 -> 4.1604373 | O11: =IF(I11<=0,O10+1,0) -> 0 | P11: =IF(I11>0,P10+1,0) -> 1
A12: 11 | B12: 多 | C12: 42122 | D12: 684 | E12: 42129 | F12: 675 | G12: 69 | H12: 4 | I12: -37824.006 | J12: =J11+I11 -> 680846.22 | K12: =I12/J12 -> -0.055554404 | L12: -0.313 | M12: 慢SAR翻转离场 | N12: =G12*D12*参数说明!$B$7/J12 -> 4.1591771 | O12: =IF(I12<=0,O11+1,0) -> 1 | P12: =IF(I12>0,P11+1,0) -> 0
A13: 12 | B13: 多 | C13: 42130 | D13: 686 | E13: 42192 | F13: 652 | G13: 65 | H13: 43 | I13: -133123.12 | J13: =J12+I12 -> 643022.22 | K13: =I13/J13 -> -0.20702725 | L13: -1.005 | M13: 慢SAR翻转离场 | N13: =G13*D13*参数说明!$B$7/J13 -> 4.160665 | O13: =IF(I13<=0,O12+1,0) -> 2 | P13: =IF(I13>0,P12+1,0) -> 0
A14: 13 | B14: 空 | C14: 42221 | D14: 614.5 | E14: 42356 | F14: 532.5 | G14: 57 | H14: 90 | I14: 280046.59 | J14: =J13+I13 -> 509899.1 | K14: =I14/J14 -> 0.54921962 | L14: 2.843 | M14: 慢SAR翻转离场 | N14: =G14*D14*参数说明!$B$7/J14 -> 4.1215802 | O14: =IF(I14<=0,O13+1,0) -> 0 | P14: =IF(I14>0,P13+1,0) -> 1
... A65: 64 | B65: 空 | C65: 46311 | D65: 1468 | E65: 46324 | F65: 1403.5 | G65: 11000 | H65: 9 | I65: 42380261 | J65: =J64+I64 -> 2.3254512e+08 | K65: =I65/J65 -> 0.18224533 | L65: 0.525 | M65: 回测结束(仍持仓) | N65: =G65*D65*参数说明!$B$7/J65 -> 4.1664173 | O65: =IF(I65<=0,O64+1,0) -> 0 | P65: =IF(I65>0,P64+1,0) -> 1

Sheet 资金曲线
A1: 日期 | B1: 焦煤加权收盘 | C1: 账户权益（元） | D1: 历史最高权益（元） | E1: 回撤 | F1: 年份
A2: 41355 | B2: 1267 | C2: 500000 | D2: =C2 -> 500000 | E2: =C2/D2-1 -> 0 | F2: =YEAR(A2) -> 2013
A3: 41358 | B3: 1259 | C3: 500000 | D3: =MAX(D2,C3) -> 500000 | E3: =C3/D3-1 -> 0 | F3: =YEAR(A3) -> 2013
A4: 41359 | B4: 1273 | C4: 500000 | D4: =MAX(D3,C4) -> 500000 | E4: =C4/D4-1 -> 0 | F4: =YEAR(A4) -> 2013
A5: 41360 | B5: 1262 | C5: 500000 | D5: =MAX(D4,C5) -> 500000 | E5: =C5/D5-1 -> 0 | F5: =YEAR(A5) -> 2013
A6: 41361 | B6: 1261 | C6: 500000 | D6: =MAX(D5,C6) -> 500000 | E6: =C6/D6-1 -> 0 | F6: =YEAR(A6) -> 2013
A7: 41362 | B7: 1242 | C7: 500000 | D7: =MAX(D6,C7) -> 500000 | E7: =C7/D7-1 -> 0 | F7: =YEAR(A7) -> 2013
A8: 41365 | B8: 1203 | C8: 500000 | D8: =MAX(D7,C8) -> 500000 | E8: =C8/D8-1 -> 0 | F8: =YEAR(A8) -> 2013
A9: 41366 | B9: 1229 | C9: 500000 | D9: =MAX(D8,C9) -> 500000 | E9: =C9/D9-1 -> 0 | F9: =YEAR(A9) -> 2013
A10: 41367 | B10: 1218 | C10: 500000 | D10: =MAX(D9,C10) -> 500000 | E10: =C10/D10-1 -> 0 | F10: =YEAR(A10) -> 2013
A11: 41372 | B11: 1221 | C11: 500000 | D11: =MAX(D10,C11) -> 500000 | E11: =C11/D11-1 -> 0 | F11: =YEAR(A11) -> 2013
A12: 41373 | B12: 1224 | C12: 500000 | D12: =MAX(D11,C12) -> 500000 | E12: =C12/D12-1 -> 0 | F12: =YEAR(A12) -> 2013
A13: 41374 | B13: 1216 | C13: 500000 | D13: =MAX(D12,C13) -> 500000 | E13: =C13/D13-1 -> 0 | F13: =YEAR(A13) -> 2013
A14: 41375 | B14: 1207 | C14: 500000 | D14: =MAX(D13,C14) -> 500000 | E14: =C14/D14-1 -> 0 | F14: =YEAR(A14) -> 2013
... A3305: 46324 | B3305: 1403 | C3305: 2.7492538e+08 | D3305: =MAX(D3304,C3305) -> 9.2602783e+08 | E3305: =C3305/D3305-1 -> -0.70311327 | F3305: =YEAR(A3305) -> 2026
